<?xml version="1.0" encoding="UTF-8"?>
<testsuite name="test1"
           tests="3"
           failures="1"
           errors="0"
           skipped="0"
           time="0.009">
  <properties />
            <testcase name="test1" time="0.008" classname="com.edu.anttest.HelloWorld">
                <failure type="java.lang.AssertionError"
                  message="expected [2] but found [1]"
              >
<![CDATA[java.lang.AssertionError: expected [2] but found [1]
  org.testng.Assert.fail(Assert.java:97)
  org.testng.Assert.assertEqualsImpl(Assert.java:136)
  org.testng.Assert.assertEquals(Assert.java:118)
  org.testng.Assert.assertEquals(Assert.java:839)
  org.testng.Assert.assertEquals(Assert.java:849)
  com.edu.anttest.HelloWorld.test1(HelloWorld.java:10)
  java.base/jdk.internal.reflect.NativeMethodAccessorImpl.invoke0(Native Method)
  java.base/jdk.internal.reflect.NativeMethodAccessorImpl.invoke(NativeMethodAccessorImpl.java:62)
  java.base/jdk.internal.reflect.DelegatingMethodAccessorImpl.invoke(DelegatingMethodAccessorImpl.java:43)
  java.base/java.lang.reflect.Method.invoke(Method.java:567)
  org.testng.internal.MethodInvocationHelper.invokeMethod(MethodInvocationHelper.java:134)
  org.testng.internal.TestInvoker.invokeMethod(TestInvoker.java:597)
  org.testng.internal.TestInvoker.invokeTestMethod(TestInvoker.java:173)
  org.testng.internal.MethodRunner.runInSequence(MethodRunner.java:46)
  org.testng.internal.TestInvoker$MethodInvocationAgent.invoke(TestInvoker.java:816)
  org.testng.internal.TestInvoker.invokeTestMethods(TestInvoker.java:146)
  org.testng.internal.TestMethodWorker.invokeTestMethods(TestMethodWorker.java:146)
  org.testng.internal.TestMethodWorker.run(TestMethodWorker.java:128)
  java.base/java.util.ArrayList.forEach(ArrayList.java:1540)
  org.testng.TestRunner.privateRun(TestRunner.java:766)
  org.testng.TestRunner.run(TestRunner.java:587)
  org.testng.SuiteRunner.runTest(SuiteRunner.java:384)
  org.testng.SuiteRunner.runSequentially(SuiteRunner.java:378)
  org.testng.SuiteRunner.privateRun(SuiteRunner.java:337)
  org.testng.SuiteRunner.run(SuiteRunner.java:286)
  org.testng.SuiteRunnerWorker.runSuite(SuiteRunnerWorker.java:53)
  org.testng.SuiteRunnerWorker.run(SuiteRunnerWorker.java:96)
  org.testng.TestNG.runSuitesSequentially(TestNG.java:1187)
  org.testng.TestNG.runSuitesLocally(TestNG.java:1109)
  org.testng.TestNG.runSuites(TestNG.java:1039)
  org.testng.TestNG.run(TestNG.java:1007)
  org.testng.remote.AbstractRemoteTestNG.run(AbstractRemoteTestNG.java:115)
  org.testng.remote.RemoteTestNG.initAndRun(RemoteTestNG.java:251)
  org.testng.remote.RemoteTestNG.main(RemoteTestNG.java:77)
]]>
      </failure>

          </testcase>
  
  
            <testcase name="test2" time="0.001" classname="com.edu.anttest.HelloWorld" />
                <testcase name="test3" time="0.000" classname="com.edu.anttest.HelloWorld" />
      
</testsuite>
